Workbook

Sheet 全部选手
A1: 排名 | B1: 编号 | C1: 省份 | D1: 类型 | E1: 姓名 | F1: 学校 | G1: 总分 | H1: 笔试 | I1: 一试 | J1: 二试 | K1: 加分
A2: =_xlfn.RANK.EQ(G2,G:G,0) -> 1 | B2: JS-003 | C2: JS | D2: A | E2: 郑煦翔 | F2: 南京外国语学校 | G2: =SUM(H2:J2)+K2 -> 705 | H2: 100 | I2: 300 | J2: 300 | K2: =IF(D2="A",5,0) -> 5
A3: =_xlfn.RANK.EQ(G3,G:G,0) -> 2 | B3: SH-001 | C3: SH | D3: A | E3: 姜博闻 | F3: 华东师范大学第二附属中学 | G3: =SUM(H3:J3)+K3 -> 704 | H3: 100 | I3: 299 | J3: 300 | K3: =IF(D3="A",5,0) -> 5
A4: =_xlfn.RANK.EQ(G4,G:G,0) -> 3 | B4: ZJ-018 | C4: ZJ | D4: B | E4: 周以山 | F4: 杭州第二中学 | G4: =SUM(H4:J4)+K4 -> 697 | H4: 100 | I4: 297 | J4: 300 | K4: =IF(D4="A",5,0) -> 0
A5: =_xlfn.RANK.EQ(G5,G:G,0) -> 4 | B5: JS-004 | C5: JS | D5: A | E5: 许淇文 | F5: 南京外国语学校 | G5: =SUM(H5:J5)+K5 -> 693 | H5: 100 | I5: 288 | J5: 300 | K5: =IF(D5="A",5,0) -> 5
A6: =_xlfn.RANK.EQ(G6,G:G,0) -> 5 | B6: SH-014 | C6: SH | D6: B | E6: 韩书简 | F6: 华东师范大学第二附属中学 | G6: =SUM(H6:J6)+K6 -> 691 | H6: 100 | I6: 299 | J6: 292 | K6: =IF(D6="A",5,0) -> 0
A7: =_xlfn.RANK.EQ(G7,G:G,0) -> 6 | B7: SD-004 | C7: SD | D7: A | E7: 杨永昌 | F7: 青岛市城阳第一高级中学 | G7: =SUM(H7:J7)+K7 -> 676 | H7: 100 | I7: 295 | J7: 276 | K7: =IF(D7="A",5,0) -> 5
A8: =_xlfn.RANK.EQ(G8,G:G,0) -> 7 | B8: GD-002 | C8: GD | D8: A | E8: 戴睿宸 | F8: 华南师范大学附属中学 | G8: =SUM(H8:J8)+K8 -> 675 | H8: 100 | I8: 298 | J8: 272 | K8: =IF(D8="A",5,0) -> 5
A9: =_xlfn.RANK.EQ(G9,G:G,0) -> 8 | B9: SC-028 | C9: SC | D9: E | E9: 蒋明睿 | F9: 成都外国语学校 | G9: =SUM(H9:J9)+K9 -> 672 | H9: 100 | I9: 300 | J9: 272 | K9: =IF(D9="A",5,0) -> 0
A10: =_xlfn.RANK.EQ(G10,G:G,0) -> 9 | B10: JS-016 | C10: JS | D10: B | E10: 张一藩 | F10: 江苏省锡山高级中学 | G10: =SUM(H10:J10)+K10 -> 661 | H10: 100 | I10: 273 | J10: 288 | K10: =IF(D10="A",5,0) -> 0
A11: =_xlfn.RANK.EQ(G11,G:G,0) -> 10 | B11: GD-004 | C11: GD | D11: A | E11: 张乐涛 | F11: 广州大学附属中学 | G11: =SUM(H11:J11)+K11 -> 648 | H11: 100 | I11: 283 | J11: 260 | K11: =IF(D11="A",5,0) -> 5
A12: =_xlfn.RANK.EQ(G12,G:G,0) -> 11 | B12: ZJ-004 | C12: ZJ | D12: A | E12: 吴旻逸 | F12: 浙江省诸暨市海亮高级中学 | G12: =SUM(H12:J12)+K12 -> 647 | H12: 100 | I12: 290 | J12: 252 | K12: =IF(D12="A",5,0) -> 5
A13: =_xlfn.RANK.EQ(G13,G:G,0) -> 12 | B13: JS-011 | C13: JS | D13: B | E13: 华高涵 | F13: 南京市金陵河西学校 | G13: =SUM(H13:J13)+K13 -> 643 | H13: 100 | I13: 275 | J13: 268 | K13: =IF(D13="A",5,0) -> 0
... A268: =_xlfn.RANK.EQ(G268,G:G,0) -> 266 | B268: GX-004 | C268: GX | D268: A | E268: 黄梓硕 | F268: 柳州高级中学 | G268: =SUM(H268:J268)+K268 -> 401 | H268: 100 | I268: 191 | J268: 105 | K268: =IF(D268="A",5,0) -> 5
A269: =_xlfn.RANK.EQ(G269,G:G,0) -> 266 | B269: SD-006 | C269: SD | D269: CA | E269: 颜庭泽 | F269: 青岛市城阳第一高级中学 | G269: =SUM(H269:J269)+K269 -> 401 | H269: 100 | I269: 164 | J269: 132 | K269: 5
A270: =_xlfn.RANK.EQ(G270,G:G,0) -> 266 | B270: SD-008 | C270: SD | D270: CA | E270: 李宸朗 | F270: 青岛市城阳第一高级中学 | G270: =SUM(H270:J270)+K270 -> 401 | H270: 100 | I270: 176 | J270: 120 | K270: 5
A271: =_xlfn.RANK.EQ(G271,G:G,0) -> 270 | B271: AH-002 | C271: AH | D271: A | E271: 韩子墨 | F271: 安徽省铜陵市第一中学 | G271: =SUM(H271:J271)+K271 -> 400 | H271: 100 | I271: 167 | J271: 128 | K271: =IF(D271="A",5,0) -> 5
A272: =_xlfn.RANK.EQ(G272,G:G,0) -> 270 | B272: SC-026 | C272: SC | D272: D | E272: 朱翼宁 | F272: 四川省绵阳中学 | G272: =SUM(H272:J272)+K272 -> 400 | H272: 100 | I272: 168 | J272: 132 | K272: =IF(D272="A",5,0) -> 0
A273: =_xlfn.RANK.EQ(G273,G:G,0) -> 272 | B273: SD-025 | C273: SD | D273: D | E273: 黄泓竣 | F273: 崂山区海尔路学校 | G273: =SUM(H273:J273)+K273 -> 399 | H273: 100 | I273: 179 | J273: 120 | K273: =IF(D273="A",5,0) -> 0
A274: =_xlfn.RANK.EQ(G274,G:G,0) -> 272 | B274: SH-018 | C274: SH | D274: D | E274: 陈思明 | F274: 华东师范大学第二附属中学前滩学校 | G274: =SUM(H274:J274)+K274 -> 399 | H274: 99 | I274: 176 | J274: 124 | K274: =IF(D274="A",5,0) -> 0
A275: =_xlfn.RANK.EQ(G275,G:G,0) -> 274 | B275: BJ-026 | C275: BJ | D275: D | E275: 李星成 | F275: 北京市第一五九中学 | G275: =SUM(H275:J275)+K275 -> 398 | H275: 99 | I275: 163 | J275: 136 | K275: =IF(D275="A",5,0) -> 0
A276: =_xlfn.RANK.EQ(G276,G:G,0) -> 274 | B276: HA-010 | C276: HA | D276: D | E276: 张浩然 | F276: 郑州外国语新枫杨学校 | G276: =SUM(H276:J276)+K276 -> 398 | H276: 100 | I276: 166 | J276: 132 | K276: =IF(D276="A",5,0) -> 0
A277: =_xlfn.RANK.EQ(G277,G:G,0) -> 276 | B277: HE-010 | C277: HE | D277: B | E277: 霍丁恺 | F277: 石家庄二中实验学校 | G277: =SUM(H277:J277)+K277 -> 397 | H277: 100 | I277: 194 | J277: 103 | K277: =IF(D277="A",5,0) -> 0
A278: =_xlfn.RANK.EQ(G278,G:G,0) -> 276 | B278: SD-017 | C278: SD | D278: B | E278: 胡淑杨 | F278: 东营市胜利第一中学 | G278: =SUM(H278:J278)+K278 -> 397 | H278: 100 | I278: 165 | J278: 132 | K278: =IF(D278="A",5,0) -> 0
A279: =_xlfn.RANK.EQ(G279,G:G,0) -> 276 | B279: SN-017 | C279: SN | D279: E | E279: 丁子博 | F279: 西安高新区第三初级中学 | G279: =SUM(H279:J279)+K279 -> 397 | H279: 100 | I279: 163 | J279: 134 | K279: =IF(D279="A",5,0) -> 0
A280: =_xlfn.RANK.EQ(G280,G:G,0) -> 279 | B280: HN-016 | C280: HN | D280: D | E280: 左凯瑞 | F280: 长沙麓山外国语实验中学 | G280: =SUM(H280:J280)+K280 -> 396 | H280: 99 | I280: 182 | J280: 115 | K280: =IF(D280="A",5,0) -> 0
A281: =_xlfn.RANK.EQ(G281,G:G,0) -> 279 | B281: SD-016 | C281: SD | D281: B | E281: 贺钰书 | F281: 山东省青岛第二中学 | G281: =SUM(H281:J281)+K281 -> 396 | H281: 100 | I281: 176 | J281: 120 | K281: =IF(D281="A",5,0) -> 0
A282: =_xlfn.RANK.EQ(G282,G:G,0) -> 279 | B282: YN-001 | C282: YN | D282: A | E282: 姜俊衔 | F282: 云南师范大学附属中学 | G282: =SUM(H282:J282)+K282 -> 396 | H282: 100 | I282: 193 | J282: 98 | K282: =IF(D282="A",5,0) -> 5
... A355: =_xlfn.RANK.EQ(G355,G:G,0) -> 352 | B355: HK-006 | C355: HK | D355: B | E355: 龍秉謙 | F355: 九龍華仁書院 | G355: =SUM(H355:J355)+K355 -> 365 | H355: 100 | I355: 166 | J355: 99 | K355: =IF(D355="A",5,0) -> 0
A356: =_xlfn.RANK.EQ(G356,G:G,0) -> 352 | B356: SD-007 | C356: SD | D356: CA | E356: 梁钰涵 | F356: 青岛市城阳第一高级中学 | G356: =SUM(H356:J356)+K356 -> 365 | H356: 100 | I356: 140 | J356: 120 | K356: 5
A357: =_xlfn.RANK.EQ(G357,G:G,0) -> 356 | B357: JL-004 | C357: JL | D357: A | E357: 董谨榕 | F357: 长春东师附中青华学校 | G357: =SUM(H357:J357)+K357 -> 364 | H357: 99 | I357: 140 | J357: 120 | K357: =IF(D357="A",5,0) -> 5
A358: =_xlfn.RANK.EQ(G358,G:G,0) -> 356 | B358: SC-020 | C358: SC | D358: D | E358: 刘子墨 | F358: 成都市成华区嘉祥外国语高级中学 | G358: =SUM(H358:J358)+K358 -> 364 | H358: 100 | I358: 142 | J358: 122 | K358: =IF(D358="A",5,0) -> 0
A359: =_xlfn.RANK.EQ(G359,G:G,0) -> 356 | B359: SD-038 | C359: SD | D359: D | E359: 马光贤 | F359: 龙口第一中学 | G359: =SUM(H359:J359)+K359 -> 364 | H359: 99 | I359: 145 | J359: 120 | K359: =IF(D359="A",5,0) -> 0
A360: =_xlfn.RANK.EQ(G360,G:G,0) -> 356 | B360: ZJ-033 | C360: ZJ | D360: D | E360: 王一丞 | F360: 宁波市效实中学 | G360: =SUM(H360:J360)+K360 -> 364 | H360: 100 | I360: 144 | J360: 120 | K360: =IF(D360="A",5,0) -> 0
A361: =_xlfn.RANK.EQ(G361,G:G,0) -> 360 | B361: HN-018 | C361: HN | D361: D | E361: 蒋金洲 | F361: 长沙市雅礼中学 | G361: =SUM(H361:J361)+K361 -> 363 | H361: 100 | I361: 163 | J361: 100 | K361: =IF(D361="A",5,0) -> 0
A362: =_xlfn.RANK.EQ(G362,G:G,0) -> 361 | B362: BJ-034 | C362: BJ | D362: D | E362: 臧兆仑 | F362: 北京市第一〇一中学 | G362: =SUM(H362:J362)+K362 -> 361 | H362: 100 | I362: 176 | J362: 85 | K362: =IF(D362="A",5,0) -> 0
A363: =_xlfn.RANK.EQ(G363,G:G,0) -> 361 | B363: FJ-019 | C363: FJ | D363: D | E363: 余若辰 | F363: 厦门市湖滨中学 | G363: =SUM(H363:J363)+K363 -> 361 | H363: 100 | I363: 166 | J363: 95 | K363: =IF(D363="A",5,0) -> 0
A364: =_xlfn.RANK.EQ(G364,G:G,0) -> 361 | B364: GD-034 | C364: GD | D364: D | E364: 杨金城 | F364: 广州大学附属中学 | G364: =SUM(H364:J364)+K364 -> 361 | H364: 100 | I364: 163 | J364: 98 | K364: =IF(D364="A",5,0) -> 0
A365: =_xlfn.RANK.EQ(G365,G:G,0) -> 364 | B365: HB-009 | C365: HB | D365: B | E365: 李俊成 | F365: 武汉市常青第一中学 | G365: =SUM(H365:J365)+K365 -> 360 | H365: 100 | I365: 132 | J365: 128 | K365: =IF(D365="A",5,0) -> 0
A366: =_xlfn.RANK.EQ(G366,G:G,0) -> 364 | B366: HN-014 | C366: HN | D366: D | E366: 易牧华 | F366: 长沙市长郡中学 | G366: =SUM(H366:J366)+K366 -> 360 | H366: 100 | I366: 170 | J366: 90 | K366: =IF(D366="A",5,0) -> 0
...

Sheet 正式选手
A1: 排名 | B1: 编号 | C1: 省份 | D1: 类型 | E1: 姓名 | F1: 学校 | G1: 总分 | H1: 笔试 | I1: 一试 | J1: 二试 | K1: 加分
A2: =_xlfn.RANK.EQ(G2,G:G,0) -> 1 | B2: JS-003 | C2: JS | D2: A | E2: 郑煦翔 | F2: 南京外国语学校 | G2: =SUM(H2:J2)+K2 -> 705 | H2: 100 | I2: 300 | J2: 300 | K2: =IF(D2="A",5,0) -> 5
A3: =_xlfn.RANK.EQ(G3,G:G,0) -> 2 | B3: SH-001 | C3: SH | D3: A | E3: 姜博闻 | F3: 华东师范大学第二附属中学 | G3: =SUM(H3:J3)+K3 -> 704 | H3: 100 | I3: 299 | J3: 300 | K3: =IF(D3="A",5,0) -> 5
A4: =_xlfn.RANK.EQ(G4,G:G,0) -> 3 | B4: ZJ-018 | C4: ZJ | D4: B | E4: 周以山 | F4: 杭州第二中学 | G4: =SUM(H4:J4)+K4 -> 697 | H4: 100 | I4: 297 | J4: 300 | K4: =IF(D4="A",5,0) -> 0
A5: =_xlfn.RANK.EQ(G5,G:G,0) -> 4 | B5: JS-004 | C5: JS | D5: A | E5: 许淇文 | F5: 南京外国语学校 | G5: =SUM(H5:J5)+K5 -> 693 | H5: 100 | I5: 288 | J5: 300 | K5: =IF(D5="A",5,0) -> 5
A6: =_xlfn.RANK.EQ(G6,G:G,0) -> 5 | B6: SH-014 | C6: SH | D6: B | E6: 韩书简 | F6: 华东师范大学第二附属中学 | G6: =SUM(H6:J6)+K6 -> 691 | H6: 100 | I6: 299 | J6: 292 | K6: =IF(D6="A",5,0) -> 0
A7: =_xlfn.RANK.EQ(G7,G:G,0) -> 6 | B7: SD-004 | C7: SD | D7: A | E7: 杨永昌 | F7: 青岛市城阳第一高级中学 | G7: =SUM(H7:J7)+K7 -> 676 | H7: 100 | I7: 295 | J7: 276 | K7: =IF(D7="A",5,0) -> 5
A8: =_xlfn.RANK.EQ(G8,G:G,0) -> 7 | B8: GD-002 | C8: GD | D8: A | E8: 戴睿宸 | F8: 华南师范大学附属中学 | G8: =SUM(H8:J8)+K8 -> 675 | H8: 100 | I8: 298 | J8: 272 | K8: =IF(D8="A",5,0) -> 5
A9: =_xlfn.RANK.EQ(G9,G:G,0) -> 8 | B9: JS-016 | C9: JS | D9: B | E9: 张一藩 | F9: 江苏省锡山高级中学 | G9: =SUM(H9:J9)+K9 -> 661 | H9: 100 | I9: 273 | J9: 288 | K9: =IF(D9="A",5,0) -> 0
A10: =_xlfn.RANK.EQ(G10,G:G,0) -> 9 | B10: GD-004 | C10: GD | D10: A | E10: 张乐涛 | F10: 广州大学附属中学 | G10: =SUM(H10:J10)+K10 -> 648 | H10: 100 | I10: 283 | J10: 260 | K10: =IF(D10="A",5,0) -> 5
A11: =_xlfn.RANK.EQ(G11,G:G,0) -> 10 | B11: ZJ-004 | C11: ZJ | D11: A | E11: 吴旻逸 | F11: 浙江省诸暨市海亮高级中学 | G11: =SUM(H11:J11)+K11 -> 647 | H11: 100 | I11: 290 | J11: 252 | K11: =IF(D11="A",5,0) -> 5
A12: =_xlfn.RANK.EQ(G12,G:G,0) -> 11 | B12: JS-011 | C12: JS | D12: B | E12: 华高涵 | F12: 南京市金陵河西学校 | G12: =SUM(H12:J12)+K12 -> 643 | H12: 100 | I12: 275 | J12: 268 | K12: =IF(D12="A",5,0) -> 0
A13: =_xlfn.RANK.EQ(G13,G:G,0) -> 12 | B13: SD-001 | C13: SD | D13: A | E13: 王茂骅 | F13: 烟台青华中学 | G13: =SUM(H13:J13)+K13 -> 641 | H13: 100 | I13: 296 | J13: 240 | K13: =IF(D13="A",5,0) -> 5
... A188: =_xlfn.RANK.EQ(G188,G:G,0) -> 187 | B188: GX-004 | C188: GX | D188: A | E188: 黄梓硕 | F188: 柳州高级中学 | G188: =SUM(H188:J188)+K188 -> 401 | H188: 100 | I188: 191 | J188: 105 | K188: =IF(D188="A",5,0) -> 5
A189: =_xlfn.RANK.EQ(G189,G:G,0) -> 187 | B189: SD-006 | C189: SD | D189: CA | E189: 颜庭泽 | F189: 青岛市城阳第一高级中学 | G189: =SUM(H189:J189)+K189 -> 401 | H189: 100 | I189: 164 | J189: 132 | K189: 5
A190: =_xlfn.RANK.EQ(G190,G:G,0) -> 187 | B190: SD-008 | C190: SD | D190: CA | E190: 李宸朗 | F190: 青岛市城阳第一高级中学 | G190: =SUM(H190:J190)+K190 -> 401 | H190: 100 | I190: 176 | J190: 120 | K190: 5
A191: =_xlfn.RANK.EQ(G191,G:G,0) -> 190 | B191: AH-002 | C191: AH | D191: A | E191: 韩子墨 | F191: 安徽省铜陵市第一中学 | G191: =SUM(H191:J191)+K191 -> 400 | H191: 100 | I191: 167 | J191: 128 | K191: =IF(D191="A",5,0) -> 5
A192: =_xlfn.RANK.EQ(G192,G:G,0) -> 191 | B192: HE-010 | C192: HE | D192: B | E192: 霍丁恺 | F192: 石家庄二中实验学校 | G192: =SUM(H192:J192)+K192 -> 397 | H192: 100 | I192: 194 | J192: 103 | K192: =IF(D192="A",5,0) -> 0
A193: =_xlfn.RANK.EQ(G193,G:G,0) -> 191 | B193: SD-017 | C193: SD | D193: B | E193: 胡淑杨 | F193: 东营市胜利第一中学 | G193: =SUM(H193:J193)+K193 -> 397 | H193: 100 | I193: 165 | J193: 132 | K193: =IF(D193="A",5,0) -> 0
A194: =_xlfn.RANK.EQ(G194,G:G,0) -> 193 | B194: SD-016 | C194: SD | D194: B | E194: 贺钰书 | F194: 山东省青岛第二中学 | G194: =SUM(H194:J194)+K194 -> 396 | H194: 100 | I194: 176 | J194: 120 | K194: =IF(D194="A",5,0) -> 0
A195: =_xlfn.RANK.EQ(G195,G:G,0) -> 193 | B195: YN-001 | C195: YN | D195: A | E195: 姜俊衔 | F195: 云南师范大学附属中学 | G195: =SUM(H195:J195)+K195 -> 396 | H195: 100 | I195: 193 | J195: 98 | K195: =IF(D195="A",5,0) -> 5
A196: =_xlfn.RANK.EQ(G196,G:G,0) -> 195 | B196: HA-008 | C196: HA | D196: B | E196: 朱轩皞 | F196: 郑州市第一中学 | G196: =SUM(H196:J196)+K196 -> 395 | H196: 100 | I196: 163 | J196: 132 | K196: =IF(D196="A",5,0) -> 0
A197: =_xlfn.RANK.EQ(G197,G:G,0) -> 195 | B197: SN-007 | C197: SN | D197: B | E197: 刘昱合 | F197: 西安高新一中沣东中学 | G197: =SUM(H197:J197)+K197 -> 395 | H197: 100 | I197: 167 | J197: 128 | K197: =IF(D197="A",5,0) -> 0
A198: =_xlfn.RANK.EQ(G198,G:G,0) -> 195 | B198: SX-001 | C198: SX | D198: A | E198: 李钰涵 | F198: 山西大学附属中学校 | G198: =SUM(H198:J198)+K198 -> 395 | H198: 100 | I198: 154 | J198: 136 | K198: =IF(D198="A",5,0) -> 5
A199: =_xlfn.RANK.EQ(G199,G:G,0) -> 198 | B199: BJ-009 | C199: BJ | D199: B | E199: 王心怡 | F199: 北京大学附属中学 | G199: =SUM(H199:J199)+K199 -> 394 | H199: 100 | I199: 171 | J199: 123 | K199: =IF(D199="A",5,0) -> 0
A200: =_xlfn.RANK.EQ(G200,G:G,0) -> 198 | B200: BJ-016 | C200: BJ | D200: B | E200: 田滨诚 | F200: 清华大学附属中学将台路校区 | G200: =SUM(H200:J200)+K200 -> 394 | H200: 100 | I200: 174 | J200: 120 | K200: =IF(D200="A",5,0) -> 0
A201: =_xlfn.RANK.EQ(G201,G:G,0) -> 198 | B201: FJ-014 | C201: FJ | D201: B | E201: 吴凯晨 | F201: 福建省福清第一中学 | G201: =SUM(H201:J201)+K201 -> 394 | H201: 100 | I201: 162 | J201: 132 | K201: =IF(D201="A",5,0) -> 0
A202: =_xlfn.RANK.EQ(G202,G:G,0) -> 201 | B202: CQ-010 | C202: CQ | D202: B | E202: 彭彦桐 | F202: 重庆市第八中学校 | G202: =SUM(H202:J202)+K202 -> 393 | H202: 100 | I202: 185 | J202: 108 | K202: =IF(D202="A",5,0) -> 0
... A233: =_xlfn.RANK.EQ(G233,G:G,0) -> 232 | B233: HK-006 | C233: HK | D233: B | E233: 龍秉謙 | F233: 九龍華仁書院 | G233: =SUM(H233:J233)+K233 -> 365 | H233: 100 | I233: 166 | J233: 99 | K233: =IF(D233="A",5,0) -> 0
A234: =_xlfn.RANK.EQ(G234,G:G,0) -> 232 | B234: SD-007 | C234: SD | D234: CA | E234: 梁钰涵 | F234: 青岛市城阳第一高级中学 | G234: =SUM(H234:J234)+K234 -> 365 | H234: 100 | I234: 140 | J234: 120 | K234: 5
A235: =_xlfn.RANK.EQ(G235,G:G,0) -> 234 | B235: JL-004 | C235: JL | D235: A | E235: 董谨榕 | F235: 长春东师附中青华学校 | G235: =SUM(H235:J235)+K235 -> 364 | H235: 99 | I235: 140 | J235: 120 | K235: =IF(D235="A",5,0) -> 5
A236: =_xlfn.RANK.EQ(G236,G:G,0) -> 235 | B236: HB-009 | C236: HB | D236: B | E236: 李俊成 | F236: 武汉市常青第一中学 | G236: =SUM(H236:J236)+K236 -> 360 | H236: 100 | I236: 132 | J236: 128 | K236: =IF(D236="A",5,0) -> 0
A237: =_xlfn.RANK.EQ(G237,G:G,0) -> 236 | B237: HI-001 | C237: HI | D237: A | E237: 关陈晓 | F237: 北京师范大学海口附属学校 | G237: =SUM(H237:J237)+K237 -> 359 | H237: 100 | I237: 156 | J237: 98 | K237: =IF(D237="A",5,0) -> 5
A238: =_xlfn.RANK.EQ(G238,G:G,0) -> 237 | B238: YN-002 | C238: YN | D238: A | E238: 王荣昊 | F238: 云南省昆明市第十中学 | G238: =SUM(H238:J238)+K238 -> 346 | H238: 100 | I238: 161 | J238: 80 | K238: =IF(D238="A",5,0) -> 5
A239: =_xlfn.RANK.EQ(G239,G:G,0) -> 238 | B239: JL-005 | C239: JL | D239: A | E239: 唐诗晴 | F239: 东北师范大学附属中学 | G239: =SUM(H239:J239)+K239 -> 345 | H239: 100 | I239: 138 | J239: 102 | K239: =IF(D239="A",5,0) -> 5
A240: =_xlfn.RANK.EQ(G240,G:G,0) -> 239 | B240: JX-004 | C240: JX | D240: A | E240: 聂鸿杰 | F240: 赣州市文清外国语学校 | G240: =SUM(H240:J240)+K240 -> 344 | H240: 100 | I240: 107 | J240: 132 | K240: =IF(D240="A",5,0) -> 5
A241: =_xlfn.RANK.EQ(G241,G:G,0) -> 240 | B241: JS-020 | C241: JS | D241: C | E241: 项承煦 | F241: 南京外国语学校 | G241: =SUM(H241:J241)+K241 -> 342 | H241: 100 | I241: 121 | J241: 121 | K241: =IF(D241="A",5,0) -> 0
A242: =_xlfn.RANK.EQ(G242,G:G,0) -> 241 | B242: BJ-012 | C242: BJ | D242: B | E242: 傅九瑞 | F242: 北京师范大学附属实验中学 | G242: =SUM(H242:J242)+K242 -> 339 | H242: 100 | I242: 141 | J242: 98 | K242: =IF(D242="A",5,0) -> 0
A243: =_xlfn.RANK.EQ(G243,G:G,0) -> 241 | B243: SX-004 | C243: SX | D243: A | E243: 姚宣羽 | F243: 运城市康杰中学 | G243: =SUM(H243:J243)+K243 -> 339 | H243: 100 | I243: 114 | J243: 120 | K243: =IF(D243="A",5,0) -> 5
A244: =_xlfn.RANK.EQ(G244,G:G,0) -> 243 | B244: HL-006 | C244: HL | D244: B | E244: 赵天放 | F244: 大庆实验中学 | G244: =SUM(H244:J244)+K244 -> 336 | H244: 100 | I244: 166 | J244: 70 | K244: =IF(D244="A",5,0) -> 0
...

Sheet 团体总分
A1: 省份 | B1: 团体总分 | C1: 全部选手 | D1: 正式选手 | E1: 非正式选手 | F1: 备注
A2: JS | B2: =SUMIFS(全部选手!G:G,全部选手!C:C,A2,全部选手!D:D,"A") -> 3004 | C2: =SUMIF(全部选手!C:C,团体总分!A2,全部选手!G:G) -> 14652 | D2: =SUMIF(正式选手!C:C,团体总分!A2,正式选手!G:G) -> 10603 | E2: =C2-D2 -> 4049
A3: GD | B3: =SUMIFS(全部选手!G:G,全部选手!C:C,A3,全部选手!D:D,"A") -> 2963 | C3: =SUMIF(全部选手!C:C,团体总分!A3,全部选手!G:G) -> 17496 | D3: =SUMIF(正式选手!C:C,团体总分!A3,正式选手!G:G) -> 9939 | E3: =C3-D3 -> 7557
A4: SD | B4: =SUMIFS(全部选手!G:G,全部选手!C:C,A4,全部选手!D:D,"A") -> 2735 | C4: =SUMIF(全部选手!C:C,团体总分!A4,全部选手!G:G) -> 17141 | D4: =SUMIF(正式选手!C:C,团体总分!A4,正式选手!G:G) -> 10216 | E4: =C4-D4 -> 6925 | F4: 山东省有 3 个 CA 类名额，若计算 CA 类，则总分第一为 3902
A5: BJ | B5: =SUMIFS(全部选手!G:G,全部选手!C:C,A5,全部选手!D:D,"A") -> 2712 | C5: =SUMIF(全部选手!C:C,团体总分!A5,全部选手!G:G) -> 16168 | D5: =SUMIF(正式选手!C:C,团体总分!A5,正式选手!G:G) -> 9645 | E5: =C5-D5 -> 6523
A6: SH | B6: =SUMIFS(全部选手!G:G,全部选手!C:C,A6,全部选手!D:D,"A") -> 2668 | C6: =SUMIF(全部选手!C:C,团体总分!A6,全部选手!G:G) -> 12393 | D6: =SUMIF(正式选手!C:C,团体总分!A6,正式选手!G:G) -> 8007 | E6: =C6-D6 -> 4386
A7: CQ | B7: =SUMIFS(全部选手!G:G,全部选手!C:C,A7,全部选手!D:D,"A") -> 2643 | C7: =SUMIF(全部选手!C:C,团体总分!A7,全部选手!G:G) -> 12826 | D7: =SUMIF(正式选手!C:C,团体总分!A7,正式选手!G:G) -> 7868 | E7: =C7-D7 -> 4958
A8: ZJ | B8: =SUMIFS(全部选手!G:G,全部选手!C:C,A8,全部选手!D:D,"A") -> 2529 | C8: =SUMIF(全部选手!C:C,团体总分!A8,全部选手!G:G) -> 20209 | D8: =SUMIF(正式选手!C:C,团体总分!A8,正式选手!G:G) -> 10456 | E8: =C8-D8 -> 9753
A9: SC | B9: =SUMIFS(全部选手!G:G,全部选手!C:C,A9,全部选手!D:D,"A") -> 2515 | C9: =SUMIF(全部选手!C:C,团体总分!A9,全部选手!G:G) -> 12240 | D9: =SUMIF(正式选手!C:C,团体总分!A9,正式选手!G:G) -> 6329 | E9: =C9-D9 -> 5911
A10: FJ | B10: =SUMIFS(全部选手!G:G,全部选手!C:C,A10,全部选手!D:D,"A") -> 2487 | C10: =SUMIF(全部选手!C:C,团体总分!A10,全部选手!G:G) -> 12278 | D10: =SUMIF(正式选手!C:C,团体总分!A10,正式选手!G:G) -> 6733 | E10: =C10-D10 -> 5545
A11: HN | B11: =SUMIFS(全部选手!G:G,全部选手!C:C,A11,全部选手!D:D,"A") -> 2460 | C11: =SUMIF(全部选手!C:C,团体总分!A11,全部选手!G:G) -> 10432 | D11: =SUMIF(正式选手!C:C,团体总分!A11,正式选手!G:G) -> 6096 | E11: =C11-D11 -> 4336
A12: HB | B12: =SUMIFS(全部选手!G:G,全部选手!C:C,A12,全部选手!D:D,"A") -> 2449 | C12: =SUMIF(全部选手!C:C,团体总分!A12,全部选手!G:G) -> 5320 | D12: =SUMIF(正式选手!C:C,团体总分!A12,正式选手!G:G) -> 4594 | E12: =C12-D12 -> 726
A13: HA | B13: =SUMIFS(全部选手!G:G,全部选手!C:C,A13,全部选手!D:D,"A") -> 2371 | C13: =SUMIF(全部选手!C:C,团体总分!A13,全部选手!G:G) -> 5118 | D13: =SUMIF(正式选手!C:C,团体总分!A13,正式选手!G:G) -> 3928 | E13: =C13-D13 -> 1190
A14: JL | B14: =SUMIFS(全部选手!G:G,全部选手!C:C,A14,全部选手!D:D,"A") -> 2085 | C14: =SUMIF(全部选手!C:C,团体总分!A14,全部选手!G:G) -> 3311 | D14: =SUMIF(正式选手!C:C,团体总分!A14,正式选手!G:G) -> 2551 | E14: =C14-D14 -> 760
A15: AH | B15: =SUMIFS(全部选手!G:G,全部选手!C:C,A15,全部选手!D:D,"A") -> 2056 | C15: =SUMIF(全部选手!C:C,团体总分!A15,全部选手!G:G) -> 4292 | D15: =SUMIF(正式选手!C:C,团体总分!A15,正式选手!G:G) -> 3927 | E15: =C15-D15 -> 365
A16: HE | B16: =SUMIFS(全部选手!G:G,全部选手!C:C,A16,全部选手!D:D,"A") -> 2054 | C16: =SUMIF(全部选手!C:C,团体总分!A16,全部选手!G:G) -> 3842 | D16: =SUMIF(正式选手!C:C,团体总分!A16,正式选手!G:G) -> 3842 | E16: =C16-D16 -> 0
... A34: OI | B34: =SUMIFS(全部选手!G:G,全部选手!C:C,A34,全部选手!D:D,"A") -> 0 | C34: =SUMIF(全部选手!C:C,团体总分!A34,全部选手!G:G) -> 1773 | D34: =SUMIF(正式选手!C:C,团体总分!A34,正式选手!G:G) -> 0 | E34: =C34-D34 -> 1773
